Workbook
Name category_STT_10_Quyensudungdat: AssetCategories!$A$1:$A$1
Name category_STT_3_Nhacongtrinhxaydung: AssetCategories!$A$104:$A$111
Name category_STT_4_Vatkientruc: AssetCategories!$A$113:$A$116
Name category_STT_5_Xeoto: AssetCategories!$A$5:$A$81
Name category_STT_6_Phuongtienvantaikhac: AssetCategories!$A$83:$A$97
Name category_STT_7_Maymocthietbi: AssetCategories!$A$118:$A$194
Name category_STT_8_Caylaunamsucvatlamviec: AssetCategories!$A$99:$A$102
Name category_STT_9_Taisancodinhhuuhinhkhac: AssetCategories!$A$3:$A$3
Name districts_STT_001_BaDinh: Wards!$AH$2:$AH$14
Name districts_STT_002_HoanKiem: Wards!$NI$2:$NI$18
Name districts_STT_003_TayHo: Wards!$KB$2:$KB$8
Name districts_STT_004_LongBien: Wards!$MX$2:$MX$14
Name districts_STT_005_CauGiay: Wards!$AL$2:$AL$8
Name districts_STT_006_DongDa: Wards!$ZD$2:$ZD$21
Name districts_STT_007_HaiBaTrung: Wards!$ZU$2:$ZU$18
Name districts_STT_008_HoangMai: Wards!$WW$2:$WW$14
Name districts_STT_009_ThanhXuan: Wards!$CY$2:$CY$11
Name districts_STT_016_SocSon: Wards!$UR$2:$UR$26
Name districts_STT_017_DongAnh: Wards!$UY$2:$UY$24
Name districts_STT_018_GiaLam: Wards!$XR$2:$XR$22
Name districts_STT_019_NamTuLiem: Wards!$HX$2:$HX$10
Name districts_STT_020_ThanhTri: Wards!$DW$2:$DW$16
Name districts_STT_021_BacTuLiem: Wards!$PO$2:$PO$13
Name districts_STT_024_HaGiang: Wards!$KX$2:$KX$8
Name districts_STT_026_DongVan: Wards!$AM$2:$AM$19
Name districts_STT_027_MeoVac: Wards!$DT$2:$DT$18
Name districts_STT_028_YenMinh: Wards!$IQ$2:$IQ$18
Name districts_STT_029_QuanBa: Wards!$KC$2:$KC$13
Name districts_STT_030_ViXuyen: Wards!$QL$2:$QL$24
Name districts_STT_031_BacMe: Wards!$KU$2:$KU$13
Name districts_STT_032_HoangSuPhi: Wards!$YJ$2:$YJ$24
Name districts_STT_033_XinMan: Wards!$GX$2:$GX$18
Name districts_STT_034_BacQuang: Wards!$JK$2:$JK$23
Name districts_STT_035_QuangBinh: Wards!$YG$2:$YG$15
Name districts_STT_040_CaoBang: Wards!$RI$2:$RI$11
Name districts_STT_042_BaoLam: Wards!$KI$2:$KI$13
Name districts_STT_043_BaoLac: Wards!$PX$2:$PX$17
Name districts_STT_045_HaQuang: Wards!$XM$2:$XM$21
Name districts_STT_047_TrungKhanh: Wards!$VI$2:$VI$21
Name districts_STT_048_HaLang: Wards!$ZQ$2:$ZQ$13
Name districts_STT_049_QuangHoa: Wards!$OK$2:$OK$19
Name districts_STT_051_HoaAn: Wards!$OL$2:$OL$15
Name districts_STT_052_NguyenBinh: Wards!$XE$2:$XE$17
Name districts_STT_053_ThachAn: Wards!$TE$2:$TE$14
Name districts_STT_058_BacKan: Wards!$NU$2:$NU$8
Name districts_STT_060_PacNam: Wards!$GB$2:$GB$10
Name districts_STT_061_BaBe: Wards!$BP$2:$BP$15
Name districts_STT_062_NganSon: Wards!$ME$2:$ME$10
Name districts_STT_063_BachThong: Wards!$PZ$2:$PZ$14
Name districts_STT_064_ChoDon: Wards!$DZ$2:$DZ$20
Name districts_STT_065_ChoMoi: Wards!$WH$2:$WH$14
Name districts_STT_066_NaRi: Wards!$VJ$2:$VJ$17
Name districts_STT_070_TuyenQuang: Wards!$SP$2:$SP$15
Name districts_STT_071_LamBinh: Wards!$BK$2:$BK$10
Name districts_STT_072_NaHang: Wards!$KZ$2:$KZ$12
Name districts_STT_073_ChiemHoa: Wards!$BQ$2:$BQ$24
Name districts_STT_074_HamYen: Wards!$ZO$2:$ZO$18
Name districts_STT_075_YenSon: Wards!$HT$2:$HT$28
Name districts_STT_076_SonDuong: Wards!$HE$2:$HE$30
Name districts_STT_080_LaoCai: Wards!$NV$2:$NV$17

Sheet ImportAsset
A1: Thông tin chung | Q1: Thông tin riêng từng loại tài sản | CP1: Thiết bị y tế | CX1: Thông tin kê khai | EB1: Thông tin khấu hao, hao mòn
A2: Danh mục tài sản (*) | B2: Loại tài sản (*) | C2: Tên tài sản (*) | D2: Đơn vị sử dụng (*) | E2: Địa điểm sử dụng | F2: Đơn vị tính | G2: Số quyết định trang cấp (*) | H2: Dự án (*) | I2: Thông tin công khai | K2: Thông tin khác | M2: Lý do tăng (*) | N2: Nguồn hình thành | O2: Giá trị nguồn hình thành | P2: Tổng nguồn hình thành | Q2: Máy móc thiết bị | X2: Đất | AB2: Nhà | AK2: Vật chất kiến trúc | AQ2: Ô tô | BN2: Phương tiện vận chuyển khác | CF2: Cây lâu năm, Súc vật làm việc | CI2: Tài sản cố định hữu hình khác/Tài sản cố định vô hình khác | CX2: Thông số kỹ thuật | CY2: Hiện trạng sử dụng (Ô tô hoặc Tài sản khác) | DE2: Hiện trạng sử dụng ( Nhà hoặc đất) | DP2: Mục đích sử dụng đất và Thông tin giấy tờ đất | EF2: Hao mòn | EJ2: Khấu hao | EO2: Còn lại
I3: Mô tả | J3: Mục đích | K3: Tài sản nhận từ đơn vị | L3: Ghi chú | Q3: Nhãn hiệu | R3: Model | S3: Số Seri | T3: Năm sản xuất | U3: Nước sản xuất | V3: Người sử dụng | W3: Hình thức bố trí sử dụng | X3: Tỉnh/thành phố | Y3: Quận/huyện | Z3: Xã/phường | AA3: Địa chỉ đất | AB3: Có quản lý đất | AC3: Thuộc khuôn viên đất | AD3: Tỉnh/thành phố | AE3: Quận/huyện | AF3: Xã/phường | AG3: Địa chỉ nhà | AH3: Số tầng | AI3: Diện tích xây dựng(m2) | AJ3: Năm xây dựng | AK3: Thuộc khuôn viên đất | AL3: Chiều dài | AM3: Diện tích xây dựng | AN3: Thể tích | AO3: Năm sản xuất | AP3: Nước sản xuất | AQ3: Được miễn thuế | AR3: Số thuế được miễn | AS3: Biển kiểm soát | AT3: Nhãn xe | AU3: Dòng xe | AV3: Tải trọng(kg) | AW3: Số chỗ ngồi | AX3: Công suất xe(kW) | AY3: Dung tích xi lanh(cc) | AZ3: Số cầu | BA3: Số khung | BB3: Số máy | BC3: Năm sản xuất | BD3: Nước sản xuất | BE3: Giấy chứng nhận đăng ký số | BF3: Ngày đăng ký | BG3: Cơ quan cấp đăng ký | BH3: Nguồn gốc xe | BI3: Màu sơn | BJ3: Người sử dụng | BK3: Hình thức bố trí sử dụng | BL3: Chức danh sử dụng | BM3: Chức danh khác | BN3: Biển kiểm soát | BO3: Nhãn hiệu | BP3: Tải trọng(kg) | BQ3: Số chỗ ngồi | BR3: Công suất xe(kW) | BS3: Dung tích xi lanh(cc) | BT3: Số khung | BU3: Số máy | BV3: Năm sản xuất | BW3: Nước sản xuất | BX3: Giấy chứng nhận đăng ký số | BY3: Ngày đăng ký | BZ3: Cơ quan cấp đăng ký | CA3: Nguồn gốc xe | CB3: Màu sơn | CC3: Người sử dụng | CD3: Hình thức bố trí sử dụng | CE3: Chức danh sử dụng | CF3: Năm sinh - trồng trọt | CG3: Nước sản xuất | CH3: Hình thức bố trí sử dụng | CI3: Nhãn hiệu | CJ3: Model | CK3: Seri | CL3: Năm sản xuất | CM3: Nước sản xuất | CN3: Người sử dụng | CO3: Hình thức bố trí sử dụng | CP3: Loại thiết bị y tế | CQ3: Nhóm thiết bị y tế | CR3: Ngày sản xuất | CS3: Hạn sử dụng | CT3: Số lưu hành | CU3: Số lô | CV3: Tên chủ sở hữu số lưu hành | CW3: Địa chỉ chủ sở hữu số lưu hành | CY3: Quản lý nhà nước | CZ3: HĐSN - Không KD | DA3: HĐSN - KD | DB3: HĐSN - LDLK | DC3: HĐSN - Cho thuê | DD3: Sử dụng khác | DE3: Trụ sở làm việc | DF3: Làm cơ sở hoạt động sự nghiệp | DG3: Kinh doanh | DH3: Cho thuê | DI3: Liên doanh, liên kết | DJ3: Sử dụng hỗn hợp | DK3: Bỏ trống | DL3: Làm nhà ở | DM3: Bị lấn chiếm | DN3: Mục đích sử dụng khác | DO3: Tổng diện tích(m2) | DP3: Mục đích sử dụng đất | DQ3: Giấy CNQSDĐ số | DR3: Ngày CNQSDĐ | DS3: Quyết định giao đất số | DT3: Ngày quyết định giao đất | DU3: Hợp đồng chuyển nhượng QSDĐ số | DV3: Ngày hợp đồng chuyển nhượng QSDĐ | DW3: Quyết định cho thuê đất số | DX3: Ngày quyết định cho thuê đất | DY3: Hợp đồng cho thuê đất số | DZ3: Ngày hợp đồng cho thuê đất | EA3: Giấy tờ khác | EB3: Cách tính khấu hao, hao mòn | EC3: Ngày mua | ED3: Ngày bắt đầu sử dụng | EE3: Ngày ghi tăng | EF3: Ngày bắt đầu tính hao mòn | EG3: Số năm sử dụng | EH3: Tỷ lệ hao mòn | EI3: Ngày kết thúc tính hao mòn | EJ3: Ngày bắt đầu trích khấu hao | EK3: Kỳ trích khấu hao | EL3: Số tháng trích khấu hao | EM3: Thời gian trích khấu hao tối thiểu | EN3: Thời gian trích khấu hao tối đa | EO3: Lũy kế | EP3: Giá trị còn lại
A4: STT_10_Quyensudungdat | B4: 10_Quyền sử dụng đất | C4: đất a16 | D4: STT_8_VienDaotaoQuocteveKhoahocVatlieuITIMS | E4: 32_phòng ban quốc tế 1 | F4: 49_căn | G4: 12_Tài liệu số 07 | H4: 8_DA0111 | I4: cạnh a15 | J4: bán nhà | K4: 10_Trung tâm Chuyển đổi số | M4: 11_Quà tặng, biếu, khuyến mãi | N4: Nguồn NSNN cấp;Ngân sách trung ương | O4: 500;2000 | P4: {=IFERROR(SUM(VALUE(_xlfn.TEXTSPLIT(O4, ";"))), "")} -> 2500 | X4: STT_01_HaNoi | Y4: STT_007_HaiBaTrung | Z4: STT_00259_DongNhan | AA4: 1000 hbt dong nhan | DE4: 10 | DF4: 40 | DG4: 200 | DH4: 40 | DI4: 200 | DJ4: 40 | DK4: 50 | DO4: =IF(SUM(DE4:DN4)=0, "", SUM(DE4:DN4)) -> 580 | EB4: Tính khấu hao | EG4: =IF(NOT(ISBLANK($B4)),VLOOKUP($B4,AssetCategories!$A:$E,5,0),"") -> 10 | EH4: =IF(NOT(ISBLANK($B4)),VLOOKUP($B4,AssetCategories!$A:$E,4,0),"") -> 10 | EJ4: 31/03/2024 | EK4: Năm | EL4: 80 | EM4: =IF(NOT(ISBLANK($B4)),VLOOKUP($B4,AssetCategories!$A:$E,2,0),"") -> 5 | EN4: =IF(NOT(ISBLANK($B4)),VLOOKUP($B4,AssetCategories!$A:$E,3,0),"") -> 10 | EP4: =IFERROR(P4-EO4, "") -> 2500
A5: STT_9_Taisancodinhhuuhinhkhac | B5: 9_Tài sản cố định hữu hình khác | C5: cây cột trụ | D5: STT_8_VienDaotaoQuocteveKhoahocVatlieuITIMS | E5: 32_phòng ban quốc tế 1 | F5: 44_căn | G5: 12_Tài liệu số 07 | H5: 7_DA022 | I5: k có | M5: 4_Quà tặng, biếu, khuyến mãi | N5: Nguồn NSNN cấp;Ngân sách trung ương | O5: 500;2000 | P5: {=IFERROR(SUM(VALUE(_xlfn.TEXTSPLIT(O5, ";"))), "")} -> 2500 | CI5: CMC | CJ5: SSSS | CK5: 09AS | CL5: 2021 | CM5: 5_Anh | CO5: 3_Phục vụ hoạt động đặc thù | CY5: Có | DA5: Có | DB5: Có | DD5: Có | DO5: =IF(SUM(DE5:DN5)=0, "", SUM(DE5:DN5)) | EB5: Tính cả hai | EC5: 01/02/2023 | ED5: 01/02/2023 | EE5: 01/02/2023 | EF5: 01/02/2023 | EG5: =IF(NOT(ISBLANK($B5)),VLOOKUP($B5,AssetCategories!$A:$E,5,0),"") -> 10 | EH5: =IF(NOT(ISBLANK($B5)),VLOOKUP($B5,AssetCategories!$A:$E,4,0),"") -> 10 | EI5: 01/02/2024 | EJ5: 31/03/2024 | EK5: Tháng | EL5: 70 | EM5: =IF(NOT(ISBLANK($B5)),VLOOKUP($B5,AssetCategories!$A:$E,2,0),"") -> 5 | EN5: =IF(NOT(ISBLANK($B5)),VLOOKUP($B5,AssetCategories!$A:$E,3,0),"") -> 10 | EP5: =IFERROR(P5-EO5, "") -> 2500
P6: {=IFERROR(SUM(VALUE(_xlfn.TEXTSPLIT(O6, ";"))), "")} | DO6: =IF(SUM(DE6:DN6)=0, "", SUM(DE6:DN6)) | EG6: =IF(NOT(ISBLANK($B6)),VLOOKUP($B6,AssetCategories!$A:$E,5,0),"") | EH6: =IF(NOT(ISBLANK($B6)),VLOOKUP($B6,AssetCategories!$A:$E,4,0),"") | EM6: =IF(NOT(ISBLANK($B6)),VLOOKUP($B6,AssetCategories!$A:$E,2,0),"") | EN6: =IF(NOT(ISBLANK($B6)),VLOOKUP($B6,AssetCategories!$A:$E,3,0),"") | EP6: =IFERROR(P6-EO6, "")
P7: {=IFERROR(SUM(VALUE(_xlfn.TEXTSPLIT(O7, ";"))), "")} | DO7: =IF(SUM(DE7:DN7)=0, "", SUM(DE7:DN7)) | EG7: =IF(NOT(ISBLANK($B7)),VLOOKUP($B7,AssetCategories!$A:$E,5,0),"") | EH7: =IF(NOT(ISBLANK($B7)),VLOOKUP($B7,AssetCategories!$A:$E,4,0),"") | EM7: =IF(NOT(ISBLANK($B7)),VLOOKUP($B7,AssetCategories!$A:$E,2,0),"") | EN7: =IF(NOT(ISBLANK($B7)),VLOOKUP($B7,AssetCategories!$A:$E,3,0),"") | EP7: =IFERROR(P7-EO7, "")
P8: {=IFERROR(SUM(VALUE(_xlfn.TEXTSPLIT(O8, ";"))), "")} | DO8: =IF(SUM(DE8:DN8)=0, "", SUM(DE8:DN8)) | EG8: =IF(NOT(ISBLANK($B8)),VLOOKUP($B8,AssetCategories!$A:$E,5,0),"") | EH8: =IF(NOT(ISBLANK($B8)),VLOOKUP($B8,AssetCategories!$A:$E,4,0),"") | EM8: =IF(NOT(ISBLANK($B8)),VLOOKUP($B8,AssetCategories!$A:$E,2,0),"") | EN8: =IF(NOT(ISBLANK($B8)),VLOOKUP($B8,AssetCategories!$A:$E,3,0),"") | EP8: =IFERROR(P8-EO8, "")
P9: {=IFERROR(SUM(VALUE(_xlfn.TEXTSPLIT(O9, ";"))), "")} | DO9: =IF(SUM(DE9:DN9)=0, "", SUM(DE9:DN9)) | EG9: =IF(NOT(ISBLANK($B9)),VLOOKUP($B9,AssetCategories!$A:$E,5,0),"") | EH9: =IF(NOT(ISBLANK($B9)),VLOOKUP($B9,AssetCategories!$A:$E,4,0),"") | EM9: =IF(NOT(ISBLANK($B9)),VLOOKUP($B9,AssetCategories!$A:$E,2,0),"") | EN9: =IF(NOT(ISBLANK($B9)),VLOOKUP($B9,AssetCategories!$A:$E,3,0),"") | EP9: =IFERROR(P9-EO9, "")
P10: {=IFERROR(SUM(VALUE(_xlfn.TEXTSPLIT(O10, ";"))), "")} | DO10: =IF(SUM(DE10:DN10)=0, "", SUM(DE10:DN10)) | EG10: =IF(NOT(ISBLANK($B10)),VLOOKUP($B10,AssetCategories!$A:$E,5,0),"") | EH10: =IF(NOT(ISBLANK($B10)),VLOOKUP($B10,AssetCategories!$A:$E,4,0),"") | EM10: =IF(NOT(ISBLANK($B10)),VLOOKUP($B10,AssetCategories!$A:$E,2,0),"") | EN10: =IF(NOT(ISBLANK($B10)),VLOOKUP($B10,AssetCategories!$A:$E,3,0),"") | EP10: =IFERROR(P10-EO10, "")
P11: {=IFERROR(SUM(VALUE(_xlfn.TEXTSPLIT(O11, ";"))), "")} | DO11: =IF(SUM(DE11:DN11)=0, "", SUM(DE11:DN11)) | EG11: =IF(NOT(ISBLANK($B11)),VLOOKUP($B11,AssetCategories!$A:$E,5,0),"") | EH11: =IF(NOT(ISBLANK($B11)),VLOOKUP($B11,AssetCategories!$A:$E,4,0),"") | EM11: =IF(NOT(ISBLANK($B11)),VLOOKUP($B11,AssetCategories!$A:$E,2,0),"") | EN11: =IF(NOT(ISBLANK($B11)),VLOOKUP($B11,AssetCategories!$A:$E,3,0),"") | EP11: =IFERROR(P11-EO11, "")
P12: {=IFERROR(SUM(VALUE(_xlfn.TEXTSPLIT(O12, ";"))), "")} | DO12: =IF(SUM(DE12:DN12)=0, "", SUM(DE12:DN12)) | EG12: =IF(NOT(ISBLANK($B12)),VLOOKUP($B12,AssetCategories!$A:$E,5,0),"") | EH12: =IF(NOT(ISBLANK($B12)),VLOOKUP($B12,AssetCategories!$A:$E,4,0),"") | EM12: =IF(NOT(ISBLANK($B12)),VLOOKUP($B12,AssetCategories!$A:$E,2,0),"") | EN12: =IF(NOT(ISBLANK($B12)),VLOOKUP($B12,AssetCategories!$A:$E,3,0),"") | EP12: =IFERROR(P12-EO12, "")
P13: {=IFERROR(SUM(VALUE(_xlfn.TEXTSPLIT(O13, ";"))), "")} | DO13: =IF(SUM(DE13:DN13)=0, "", SUM(DE13:DN13)) | EG13: =IF(NOT(ISBLANK($B13)),VLOOKUP($B13,AssetCategories!$A:$E,5,0),"") | EH13: =IF(NOT(ISBLANK($B13)),VLOOKUP($B13,AssetCategories!$A:$E,4,0),"") | EM13: =IF(NOT(ISBLANK($B13)),VLOOKUP($B13,AssetCategories!$A:$E,2,0),"") | EN13: =IF(NOT(ISBLANK($B13)),VLOOKUP($B13,AssetCategories!$A:$E,3,0),"") | EP13: =IFERROR(P13-EO13, "")
P14: {=IFERROR(SUM(VALUE(_xlfn.TEXTSPLIT(O14, ";"))), "")} | DO14: =IF(SUM(DE14:DN14)=0, "", SUM(DE14:DN14)) | EG14: =IF(NOT(ISBLANK($B14)),VLOOKUP($B14,AssetCategories!$A:$E,5,0),"") | EH14: =IF(NOT(ISBLANK($B14)),VLOOKUP($B14,AssetCategories!$A:$E,4,0),"") | EM14: =IF(NOT(ISBLANK($B14)),VLOOKUP($B14,AssetCategories!$A:$E,2,0),"") | EN14: =IF(NOT(ISBLANK($B14)),VLOOKUP($B14,AssetCategories!$A:$E,3,0),"") | EP14: =IFERROR(P14-EO14, "")
P15: {=IFERROR(SUM(VALUE(_xlfn.TEXTSPLIT(O15, ";"))), "")} | DO15: =IF(SUM(DE15:DN15)=0, "", SUM(DE15:DN15)) | EG15: =IF(NOT(ISBLANK($B15)),VLOOKUP($B15,AssetCategories!$A:$E,5,0),"") | EH15: =IF(NOT(ISBLANK($B15)),VLOOKUP($B15,AssetCategories!$A:$E,4,0),"") | EM15: =IF(NOT(ISBLANK($B15)),VLOOKUP($B15,AssetCategories!$A:$E,2,0),"") | EN15: =IF(NOT(ISBLANK($B15)),VLOOKUP($B15,AssetCategories!$A:$E,3,0),"") | EP15: =IFERROR(P15-EO15, "")
P16: {=IFERROR(SUM(VALUE(_xlfn.TEXTSPLIT(O16, ";"))), "")} | DO16: =IF(SUM(DE16:DN16)=0, "", SUM(DE16:DN16)) | EG16: =IF(NOT(ISBLANK($B16)),VLOOKUP($B16,AssetCategories!$A:$E,5,0),"") | EH16: =IF(NOT(ISBLANK($B16)),VLOOKUP($B16,AssetCategories!$A:$E,4,0),"") | EM16: =IF(NOT(ISBLANK($B16)),VLOOKUP($B16,AssetCategories!$A:$E,2,0),"") | EN16: =IF(NOT(ISBLANK($B16)),VLOOKUP($B16,AssetCategories!$A:$E,3,0),"") | EP16: =IFERROR(P16-EO16, "")
P17: {=IFERROR(SUM(VALUE(_xlfn.TEXTSPLIT(O17, ";"))), "")} | DO17: =IF(SUM(DE17:DN17)=0, "", SUM(DE17:DN17)) | EG17: =IF(NOT(ISBLANK($B17)),VLOOKUP($B17,AssetCategories!$A:$E,5,0),"") | EH17: =IF(NOT(ISBLANK($B17)),VLOOKUP($B17,AssetCategories!$A:$E,4,0),"") | EM17: =IF(NOT(ISBLANK($B17)),VLOOKUP($B17,AssetCategories!$A:$E,2,0),"") | EN17: =IF(NOT(ISBLANK($B17)),VLOOKUP($B17,AssetCategories!$A:$E,3,0),"") | EP17: =IFERROR(P17-EO17, "")
... P2001: {=IFERROR(SUM(VALUE(_xlfn.TEXTSPLIT(O2001, ";"))), "")} | DO2001: =IF(SUM(DE2001:DN2001)=0, "", SUM(DE2001:DN2001)) | EG2001: =IF(NOT(ISBLANK($B2001)),VLOOKUP($B2001,AssetCategories!$A:$E,5,0),"") | EH2001: =IF(NOT(ISBLANK($B2001)),VLOOKUP($B2001,AssetCategories!$A:$E,4,0),"") | EM2001: =IF(NOT(ISBLANK($B2001)),VLOOKUP($B2001,AssetCategories!$A:$E,2,0),"") | EN2001: =IF(NOT(ISBLANK($B2001)),VLOOKUP($B2001,AssetCategories!$A:$E,3,0),"") | EP2001: =IFERROR(P2001-EO2001, "")
P2002: {=IFERROR(SUM(VALUE(_xlfn.TEXTSPLIT(O2002, ";"))), "")} | DO2002: =IF(SUM(DE2002:DN2002)=0, "", SUM(DE2002:DN2002)) | EP2002: =IFERROR(P2002-EO2002, "")
P2003: {=IFERROR(SUM(VALUE(_xlfn.TEXTSPLIT(O2003, ";"))), "")} | DO2003: =IF(SUM(DE2003:DN2003)=0, "", SUM(DE2003:DN2003)) | EP2003: =IFERROR(P2003-EO2003, "")
P2004: {=IFERROR(SUM(VALUE(_xlfn.TEXTSPLIT(O2004, ";"))), "")} | DO2004: =IF(SUM(DE2004:DN2004)=0, "", SUM(DE2004:DN2004)) | EP2004: =IFERROR(P2004-EO2004, "")
P2005: {=IFERROR(SUM(VALUE(_xlfn.TEXTSPLIT(O2005, ";"))), "")} | DO2005: =IF(SUM(DE2005:DN2005)=0, "", SUM(DE2005:DN2005)) | EP2005: =IFERROR(P2005-EO2005, "")
P2006: {=IFERROR(SUM(VALUE(_xlfn.TEXTSPLIT(O2006, ";"))), "")} | DO2006: =IF(SUM(DE2006:DN2006)=0, "", SUM(DE2006:DN2006)) | EP2006: =IFERROR(P2006-EO2006, "")
P2007: {=IFERROR(SUM(VALUE(_xlfn.TEXTSPLIT(O2007, ";"))), "")} | DO2007: =IF(SUM(DE2007:DN2007)=0, "", SUM(DE2007:DN2007)) | EP2007: =IFERROR(P2007-EO2007, "")
P2008: {=IFERROR(SUM(VALUE(_xlfn.TEXTSPLIT(O2008, ";"))), "")} | DO2008: =IF(SUM(DE2008:DN2008)=0, "", SUM(DE2008:DN2008)) | EP2008: =IFERROR(P2008-EO2008, "")
P2009: {=IFERROR(SUM(VALUE(_xlfn.TEXTSPLIT(O2009, ";"))), "")} | DO2009: =IF(SUM(DE2009:DN2009)=0, "", SUM(DE2009:DN2009)) | EP2009: =IFERROR(P2009-EO2009, "")
P2010: {=IFERROR(SUM(VALUE(_xlfn.TEXTSPLIT(O2010, ";"))), "")} | DO2010: =IF(SUM(DE2010:DN2010)=0, "", SUM(DE2010:DN2010)) | EP2010: =IFERROR(P2010-EO2010, "")
P2011: {=IFERROR(SUM(VALUE(_xlfn.TEXTSPLIT(O2011, ";"))), "")} | DO2011: =IF(SUM(DE2011:DN2011)=0, "", SUM(DE2011:DN2011)) | EP2011: =IFERROR(P2011-EO2011, "")
P2012: {=IFERROR(SUM(VALUE(_xlfn.TEXTSPLIT(O2012, ";"))), "")} | DO2012: =IF(SUM(DE2012:DN2012)=0, "", SUM(DE2012:DN2012)) | EP2012: =IFERROR(P2012-EO2012, "")
P2013: {=IFERROR(SUM(VALUE(_xlfn.TEXTSPLIT(O2013, ";"))), "")} | DO2013: =IF(SUM(DE2013:DN2013)=0, "", SUM(DE2013:DN2013)) | EP2013: =IFERROR(P2013-EO2013, "")
... P2058: {=IFERROR(SUM(VALUE(_xlfn.TEXTSPLIT(O2058, ";"))), "")} | DO2058: =IF(SUM(DE2058:DN2058)=0, "", SUM(DE2058:DN2058)) | EP2058: =IFERROR(P2058-EO2058, "")
P2059: {=IFERROR(SUM(VALUE(_xlfn.TEXTSPLIT(O2059, ";"))), "")} | EP2059: =IFERROR(P2059-EO2059, "")
P2060: {=IFERROR(SUM(VALUE(_xlfn.TEXTSPLIT(O2060, ";"))), "")} | EP2060: =IFERROR(P2060-EO2060, "")
P2061: {=IFERROR(SUM(VALUE(_xlfn.TEXTSPLIT(O2061, ";"))), "")} | EP2061: =IFERROR(P2061-EO2061, "")
P2062: {=IFERROR(SUM(VALUE(_xlfn.TEXTSPLIT(O2062, ";"))), "")} | EP2062: =IFERROR(P2062-EO2062, "")
P2063: {=IFERROR(SUM(VALUE(_xlfn.TEXTSPLIT(O2063, ";"))), "")} | EP2063: =IFERROR(P2063-EO2063, "")
P2064: {=IFERROR(SUM(VALUE(_xlfn.TEXTSPLIT(O2064, ";"))), "")} | EP2064: =IFERROR(P2064-EO2064, "")
P2065: {=IFERROR(SUM(VALUE(_xlfn.TEXTSPLIT(O2065, ";"))), "")} | EP2065: =IFERROR(P2065-EO2065, "")
P2066: {=IFERROR(SUM(VALUE(_xlfn.TEXTSPLIT(O2066, ";"))), "")} | EP2066: =IFERROR(P2066-EO2066, "")
P2067: {=IFERROR(SUM(VALUE(_xlfn.TEXTSPLIT(O2067, ";"))), "")} | EP2067: =IFERROR(P2067-EO2067, "")
...

Sheet Hướng dẫn nhập thông tin
A1: Thông tin chung | Q1: Thông tin riêng từng loại tài sản | CP1: Thiết bị y tế | CX1: Thông tin kê khai | EB1: Thông tin khấu hao, hao mòn
A2: Danh mục tài sản (*) | B2: Loại tài sản (*) | C2: Tên tài sản (*) | D2: Đơn vị sử dụng (*) | E2: Địa điểm sử dụng | F2: Đơn vị tính | G2: Số quyết định trang cấp (*) | H2: Dự án (*) | I2: Thông tin công khai | K2: Thông tin khác | M2: Lý do tăng (*) | N2: Nguồn hình thành | O2: Giá trị nguồn hình thành | P2: Tổng nguồn hình thành | Q2: Máy móc thiết bị | X2: Đất | AB2: Nhà | AK2: Vật chất kiến trúc | AQ2: Ô tô | BN2: Phương tiện vận chuyển khác | CF2: Cây lâu năm, Súc vật làm việc | CI2: Tài sản cố định hữu hình khác/Tài sản cố định vô hình khác | CX2: Thông số kỹ thuật | CY2: Hiện trạng sử dụng (Ô tô hoặc Tài sản khác) | DE2: Hiện trạng sử dụng ( Nhà hoặc đất) | DP2: Mục đích sử dụng đất và Thông tin giấy tờ đất | EF2: Hao mòn | EJ2: Khấu hao | EO2: Còn lại
I3: Mô tả | J3: Mục đích | K3: Tài sản nhận từ đơn vị | L3: Ghi chú | Q3: Nhãn hiệu | R3: Model | S3: Số Seri | T3: Năm sản xuất | U3: Nước sản xuất | V3: Người sử dụng | W3: Hình thức bố trí sử dụng | X3: Tỉnh/thành phố | Y3: Quận/huyện | Z3: Xã/phường | AA3: Địa chỉ đất | AB3: Có quản lý đất | AC3: Thuộc khuôn viên đất | AD3: Tỉnh/thành phố | AE3: Quận/huyện | AF3: Xã/phường | AG3: Địa chỉ nhà | AH3: Số tầng | AI3: Diện tích xây dựng(m2) | AJ3: Năm xây dựng | AK3: Thuộc khuôn viên đất | AL3: Chiều dài | AM3: Diện tích xây dựng | AN3: Thể tích | AO3: Năm sản xuất | AP3: Nước sản xuất | AQ3: Được miễn thuế | AR3: Số thuế được miễn | AS3: Biển kiểm soát | AT3: Nhãn xe | AU3: Dòng xe | AV3: Tải trọng(kg) | AW3: Số chỗ ngồi | AX3: Công suất xe(kW) | AY3: Dung tích xi lanh(cc) | AZ3: Số cầu | BA3: Số khung | BB3: Số máy | BC3: Năm sản xuất | BD3: Nước sản xuất | BE3: Giấy chứng nhận đăng ký số | BF3: Ngày đăng ký | BG3: Cơ quan cấp đăng ký | BH3: Nguồn gốc xe | BI3: Màu sơn | BJ3: Người sử dụng | BK3: Hình thức bố trí sử dụng | BL3: Chức danh sử dụng | BM3: Chức danh khác | BN3: Biển kiểm soát | BO3: Nhãn hiệu | BP3: Tải trọng(kg) | BQ3: Số chỗ ngồi | BR3: Công suất xe(kW) | BS3: Dung tích xi lanh(cc) | BT3: Số khung | BU3: Số máy | BV3: Năm sản xuất | BW3: Nước sản xuất | BX3: Giấy chứng nhận đăng ký số | BY3: Ngày đăng ký | BZ3: Cơ quan cấp đăng ký | CA3: Nguồn gốc xe | CB3: Màu sơn | CC3: Người sử dụng | CD3: Hình thức bố trí sử dụng | CE3: Chức danh sử dụng | CF3: Năm sinh - trồng trọt | CG3: Nước sản xuất | CH3: Hình thức bố trí sử dụng | CI3: Nhãn hiệu | CJ3: Model | CK3: Seri | CL3: Năm sản xuất | CM3: Nước sản xuất | CN3: Người sử dụng | CO3: Hình thức bố trí sử dụng | CP3: Loại thiết bị y tế | CQ3: Nhóm thiết bị y tế | CR3: Ngày sản xuất | CS3: Hạn sử dụng | CT3: Số lưu hành | CU3: Số lô | CV3: Tên chủ sở hữu số lưu hành | CW3: Địa chỉ chủ sở hữu số lưu hành | CY3: Quản lý nhà nước | CZ3: HĐSN - Không KD | DA3: HĐSN - KD | DB3: HĐSN - LDLK | DC3: HĐSN - Cho thuê | DD3: Sử dụng khác | DE3: Trụ sở làm việc | DF3: Làm cơ sở hoạt động sự nghiệp | DG3: Kinh doanh | DH3: Cho thuê | DI3: Liên doanh, liên kết | DJ3: Sử dụng hỗn hợp | DK3: Bỏ trống | DL3: Làm nhà ở | DM3: Bị lấn chiếm | DN3: Mục đích sử dụng khác | DO3: Tổng diện tích(m2) | DP3: Mục đích sử dụng đất | DQ3: Giấy CNQSDĐ số | DR3: Ngày CNQSDĐ | DS3: Quyết định giao đất số | DT3: Ngày quyết định giao đất | DU3: Hợp đồng chuyển nhượng QSDĐ số | DV3: Ngày hợp đồng chuyển nhượng QSDĐ | DW3: Quyết định cho thuê đất số | DX3: Ngày quyết định cho thuê đất | DY3: Hợp đồng cho thuê đất số | DZ3: Ngày hợp đồng cho thuê đất | EA3: Giấy tờ khác | EB3: Cách tính khấu hao, hao mòn | EC3: Ngày mua | ED3: Ngày bắt đầu sử dụng | EE3: Ngày ghi tăng | EF3: Ngày bắt đầu tính hao mòn | EG3: Số năm sử dụng | EH3: Tỷ lệ hao mòn | EI3: Ngày kết thúc tính hao mòn | EJ3: Ngày bắt đầu trích khấu hao | EK3: Kỳ trích khấu hao | EL3: Số tháng trích khấu hao | EM3: Thời gian trích khấu hao tối thiểu | EN3: Thời gian trích khấu hao tối đa | EO3: Lũy kế | EP3: Giá trị còn lại
A4: Bao gồm các nhóm loại tài sản được quy định phân loại trong thông tư 23/2023/TT-BTC: 1. Tài sản cố định hữu hình - Nhà, công trình xây dựng - Vật kiến trúc - Xe ô tô - Phương tiện vận tải khác - Máy móc thiết bị - Cây lâu năm, súc vật làm việc và/hoặc cho sản phẩm - Tài sản cố định hữu hình khác 2. Tài sản cố định vô định hình 3. Tài sản cố định đặc thù | B4: Loại tài sản được cung cấp theo danh mục loại tài sản, hao mòn và số năm sử dụng ban hành kèm theo thông tư 23/2023/TT-BTC. | C4: Tên tài sản được sử dụng để phân biệt các tài sản. Người dùng nên đặt tên tài sản theo cú pháp quy ước để thuận tiện cho việc tra cứu, tìm kiếm. | D4: Đơn vị sử dụng là trường, khoa, phòng ban trung tâm hoặc các đơn vị cấp dưới trực thuộc được bàn giao sử dụng tài sản. | E4: Địa điểm sử dụng là vị trí cụ thể đặt, sử dụng tài sản đó trong đơn vị được cấp. Ví dụ: Phòng ban A có thể có: 2 phòng là 101, 102 và tài sản đó được sử dụng ở phòng 102 | F4: Đối với mỗi loại tài sản, danh sách đơn vị tính sẽ thay đổi phù hợp với từng tài sản.Ví dụ: Máy móc thiết bị sẽ có đơn vị tính là:"Cái, Chiếc, ..." | G4: Số hiệu quyết định cấp trên có thẩm quyền ra quyết định trang cấp, mua sắm, tiếp nhận,... tài sản | H4: Tên của dự án mà ài sản được sử dụng để phục vụ | I4: Mô tả thông tin của tài sản cố định | J4: Mục đích mà sử dụng cho từng loại tài sản theo nhu cầu | K4: Đơn vị bàn giao tài sản này | L4: Ghi chú về thông tin tài sản nếu có | M4: Lý do tăng của mỗi loại tài sản như: Mua sắm, kiểm kê, đầu tư,… | N4: Nguồn hình thành là các nguồn vốn hoặc tài chính được sử dụng để mua sắm, xây dựng hoặc tạo ra tài sản cố định cho doanh nghiệp hoặc tổ chức. Từ đó tính ra giá trị nguyên giá ghi theo sổ kế toán. Khi nhập thông tin trong người dùng nhập thông tin các nguồn hình thành và các nhau bởi dấu ";" ví dụ như: Ngân sách Huyện tự chủ;Ngân sách Xã;Nguồn tài trợ - viện trợ | O4: Đây là giá trị của mỗi nguồn hình thành được nhập ở ô bên cạnh. Người nhập sẽ điện giá trị của các nguồn hình thành tương ứng với loại nguồn hình thành bên cạnh ví dụ có 3 nguồn hình thành bên cạnh với giá trị lần lượt là:Ngân sách Huyện tự chủ là 300;Ngân sách Xã là 400 ;Nguồn tài trợ - viện trợ là 500 thì ở ô này ta sẽ điền thông tin là :300;400;500 | P4: là tổng các giá trị của nguồn hình thành bên cạnh | Q4: thông tin nhãn hiệu của thiết bị này | R4: Đây là số hiệu quy định của dòng sản phẩm được ghi trên mỗi thiết bị cùng với thông số kỹ thuật | S4: Mã số riêng của từng thiết bị được nhà sản xuất cung cấp ghi trên thiết bị | T4: Năm thiết bị được sản xuất | U4: Quốc gia sản xuất ra thiết bị | V4: Người thuộctrong đơn vị mà được bàn giao sử dụng thiết bị đó | W4: Gồm các hình thức sau: Phục vụ chức danh có tiêu chuẩn Phục vụ công tác chung Phục vụ hoạt động đặc thù Sử dụng khác Điều chuyển | X4: Thông tin tỉnh/thành phố của địa chỉ đất | Y4: Thông tin quận/huyện của địa chỉ đất | Z4: Thông tin xã/phường của địa chỉ đất | AA4: thông tin cụ thể của địa chỉ đất | AB4: Thông tin bao gồm: "Có hoặc Không" | AC4: Nếu người dùng chọn có quản lý đất: thì ở cột này sẽ chọn thông tin về tài sản đất mà tòa nhà này được xây dựng trên | AD4: Thông tin tỉnh/thành phố của địa chỉ nhà | AE4: Thông tin quận/huyện của địa chỉ nhà | AF4: Thông tin xã/phường của địa chỉ nhà | AG4: thông tin cụ thể của địa chỉ nhà | AH4: Số tầng của ngôi/tòa nhà | AI4: Diện tích của tòa nhà đó | AJ4: Năm tòa nhà bắt đầu xây dựng | AK4: cột này sẽ chọn thông tin về tài sản đất mà vật kiến trúc này được xây dựng, đặt trên | AL4: Chiều dài của vật kiến trúc | AM4: Diện tích của vật kiến trúc | AN4: Thể tích của vật kiến trúc | AO4: Thông tin nước sản xuất của vật kiến trúc | AP4: Thông tin nước sản xuất của vật kiến trúc | AQ4: Ô tô có được miễn thuế hay không(Người sử dụng sẽ chọn Có hoăc Không) | AR4: Nếu người chọn Có được miễn thuế thì điền thêm thông tin số thuế được miễn vào | AS4: Biển kiểm soát của xe ô tô | AT4: Nhãn hiệu của xe để phân biệt giữa các xe | AU4: Dòng xe ô tô | AV4: Khối lượng hành hóa mà xe có thể vận chuyển | AW4: Số chỗ ngồi trong xe ô tô | AX4: Biểu thị tốc độ tối đa mà xe có thể đạt được | AY4: Thể tích của động cơ | AZ4: Ghi theo số cầu đối với ô tô có từ 4 đến 8 chỗ | BA4: Là chuỗi ký tự trên xe cung cấp thông tin về nhãn hiệu,động cơ,.. | BB4: Số máy giúp xác định động cơ cụ thể được lắp trong xe là gì | BC4: Thông tin năm sản xuất của ô tô | BD4: Thông tin nước sản xuất của ô tô | BE4: Giấy xác nhận quyền sở hữu của phương tiện | BF4: Ngày đăng ký xe | BG4: cơ quan cấp giấy xác nhận quyền sở hữu của phương tiện | BH4: bao gồm: Xe nhập khẩu, sản xuất lắp ráp trong nước, Xe bị tịch thu | BI4: Màu sơn của xe | BJ4: Người thuộc trong đơn vị mà được bàn giao sử dụng ô tô | BK4: Gồm các hình thức sau: Phục vụ chức danh có tiêu chuẩn Phục vụ công tác chung Phục vụ hoạt động đặc thù Sử dụng khác Điều chuyển | BL4: Chức danh được sử dụng với loại ô tô chuyên phục vụ chức danh này | BM4: Chức danh khác được sử dụng với loại ô tô chuyên phục vụ chức danh này | BN4: Nhãn hiệu của xe để phân biệt giữa các xe | BO4: Dòng xe ô tô | BP4: Khối lượng hành hóa mà xe có thể vận chuyển | BQ4: Số chỗ ngồi trong xe ô tô | BR4: Biểu thị tốc độ tối đa mà xe có thể đạt được | BS4: Thể tích của động cơ | BT4: Là chuỗi ký tự trên xe cung cấp thông tin về nhãn hiệu,động cơ,.. | BU4: Số máy giúp xác định động cơ cụ thể được lắp trong xe là gì | BV4: Thông tin năm sản xuất của phương tiện | BW4: Thông tin nước sản xuất của phương tiện | BX4: Giấy xác nhận quyền sở hữu của phương tiện | BY4: Ngày đăng ký xe | BZ4: cơ quan cấp giấy xác nhận quyền sở hữu của phương tiện | CA4: gồm một vài nguồn như: Nhập khẩu, sản xuất lắp ráp trong nước, bị tịch thu | CB4: Màu sơn của phương tiện | CC4: Người thuộc trong đơn vị mà được bàn giao sử dụng phương tiện | CD4: Gồm các hình thức sau: Phục vụ chức danh có tiêu chuẩn Phục vụ công tác chung Phục vụ hoạt động đặc thù Sử dụng khác Điều chuyển | CE4: Chức danh được sử dụng với loại phương tiện này | CF4: Năm hình thành tài sản này | CG4: Thông tin nước sản xuất của tài sản | CH4: Gồm các hình thức sau: Phục vụ chức danh có tiêu chuẩn Phục vụ công tác chung Phục vụ hoạt động đặc thù Sử dụng khác Điều chuyển | CI4: thông tin nhãn hiệu của tài sản này | CJ4: Đây là số hiệu quy định của dòng sản phẩm được ghi trên mỗi tài sản cùng với thông số kỹ thuật | CK4: Mã số riêng của từng thiết bị được nhà sản xuất cung cấp ghi trên tài sản | CL4: Năm tài sản được sản xuất | CM4: Quốc gia sản xuất ra tài sản | CN4: Người thuộctrong đơn vị mà được bàn giao sử dụng tài sản đó | CO4: Gồm các hình thức sau: Phục vụ chức danh có tiêu chuẩn Phục vụ công tác chung Phục vụ hoạt động đặc thù Sử dụng khác Điều chuyển | CP4: Danh sách các trang thiết bị y tế | CQ4: Thiết bị y tế được chia thành 4 nhóm: 1. Trang thiết bị y tế thuộc loại A là trang thiết bị y tế có mức độ rủi ro thấp. 2. Trang thiết bị y tế thuộc loại B là trang thiết bị y tế có mức độ rủi ro trung bình thấp. 3. Trang thiết bị y tế thuộc loại C là trang thiết bị y tế có mức độ rủi ro trung bình cao. 4. Trang thiết bị y tế thuộc loại D là trang thiết bị y tế có mức độ rủi ro cao. | CR4: Ngày sản xuất ghi trên bao bì, thông tin đi kèm của sản phẩm. | CS4: Thời hạn được nhà sản xuất cung cấp đảm bảo sản phẩm an toàn, hiệu quả. | CT4: Số lưu hành của trang thiết bị y tế là: Số công bố tiêu chuẩn áp dụng đối với trang thiết bị y tế thuộc loại A, B; hoặc Số giấy chứng nhận đăng ký lưu hành đối với trang thiết bị y tế thuộc loại C, D. | CU4: Mã số hiệu sản xuất nhóm sản phẩm. | CV4: Chủ sở hữu số lưu hành là tổ chức công bố tiêu chuẩn áp dụng đối với trang thiết bị y tế thuộc loại A, B hoặc tổ chức được cấp giấy chứng nhận đăng ký lưu hành đối với trang thiết bị y tế thuộc loại C, D. | CW4: Địa chỉ của cá nhân hoặc tổ chức sở hữu số đăng ký lưu hành thiết bị y tế | CX4: Thông số kỹ thuật của các loại tài sản khác đất với nhà | CY4: Người dùng chọn:Có hoặc Không nếu tài sản đang có hiện trạng sử dụng như này | CZ4: Người dùng chọn:Có hoặc Không nếu tài sản đang có hiện trạng sử dụng như này | DA4: Người dùng chọn:Có hoặc Không nếu tài sản đang có hiện trạng sử dụng như này | DB4: Người dùng chọn:Có hoặc Không nếu tài sản đang có hiện trạng sử dụng như này | DC4: Người dùng chọn:Có hoặc Không nếu tài sản đang có hiện trạng sử dụng như này | DD4: Người dùng chọn:Có hoặc Không nếu tài sản đang có hiện trạng sử dụng như này | DE4: Diện tích mà tài sản Nhà hoặc Đất được dùng làm trụ sở làm việc | DF4: Diện tích mà tài sản Nhà hoặc Đất được dùng làm cơ sở hoạt động sử nghiệp | DG4: Diện tích mà tài sản Nhà hoặc Đất được dùng làm kinh doanh | DH4: Diện tích mà tài sản Nhà hoặc Đất được dùng cho thuê | DI4: Diện tích mà tài sản Nhà hoặc Đất được dùng làm liên doanh, liên kết mất 100m2 thì người dùng chỉ cần nhập:100 | DJ4: Diện tích mà tài sản Nhà hoặc Đất được sử dụng hỗn hợp 100m2 thì người dùng chỉ cần nhập:100 | DK4: Diện tích mà tài sản Nhà hoặc Đất bị bỏ trống 100 m2 thì người dùng chỉ cần nhập:100 | DL4: Diện tích mà tài sản Nhà hoặc Đất được dùng làm nhà ở mất 200 m2 thì người dùng chỉ cần nhập:200 | DM4: Diện tích mà tài sản Nhà hoặc Đất bị lấn chiếm 100 m2 thì người dùng chỉ cần nhập:100 | DN4: Diện tích mà tài sản Nhà hoặc Đất được dùng làm với mục đích khác ví dụ:100 m2, thì người dùng chỉ cần nhập:100 | DO4: Tổng diện tích được tính từ các phần trước cộng vào | DP4: Người dùng sẽ chọn các mục đích của đất được sử dụng nhằm để làm gì. Ví dụ: Y tế, Giáo dục,… | DQ4: Thông tin giấy tờ số chứng nhận quyền sử dụng đất | DR4: Ngày CNQSDĐ người dùng sẽ nhập theo định dạng DD/MM/YYYY. Ví dụ ngày 31 tháng 3 năm 2024 thì sẽ điền là: 31/03/2024 | DS4: Thông tin giấy tờ, số quyết định giao đất | DT4: Ngày quyết định giao đất người dùng sẽ nhập theo định dạng DD/MM/YYYY. Ví dụ ngày 31 tháng 3 năm 2024 thì sẽ điền là: 31/03/2024 | DU4: Thông tin giấy tờ, số Hợp đồng chuyển nhượng quyền sử dụng đất | DV4: Ngày hợp đồng chuyển nhượng QSDĐ người dùng sẽ nhập theo định dạng DD/MM/YYYY. Ví dụ ngày 31 tháng 3 năm 2024 thì sẽ điền là: 31/03/2024 | DW4: Thông tin giấy tờ, số quyết định cho thuê đất | DX4: Ngày quyết định cho thuê đất người dùng sẽ nhập theo định dạng DD/MM/YYYY. Ví dụ ngày 31 tháng 3 năm 2024 thì sẽ điền là: 31/03/2024 | DY4: Thông tin giấy tờ về hợp đồng cho thuê đất | DZ4: Ngày hợp đồng cho thuê đất người dùng sẽ nhập theo định dạng DD/MM/YYYY. Ví dụ ngày 31 tháng 3 năm 2024 thì sẽ điền là: 31/03/2024 | EA4: Thông tin giấy tờ liên quan đến các thủ tục khác | EB4: Người dùng có thể chọn: Tính hao mòn, tính khấu hao, tính cả hai tùy vào mục đích | EC4: Ngày mua tài sản người dùng sẽ nhập theo định dạng DD/MM/YYYY. Ví dụ ngày 31 tháng 3 năm 2024 thì sẽ điền là: 31/03/2024 | ED4: Ngày bắt đầu sử dụng tài sản người dùng sẽ nhập theo định dạng DD/MM/YYYY. Ví dụ ngày 31 tháng 3 năm 2024 thì sẽ điền là: 31/03/2024 | EE4: Ngày bắt đầu ghi tăng tài sản người dùng sẽ nhập theo định dạng DD/MM/YYYY. Ví dụ ngày 31 tháng 3 năm 2024 thì sẽ điền là: 31/03/2024 | EF4: Ngày bắt đầu tính hao mòn đối với tài sản người dùng sẽ nhập theo định dạng DD/MM/YYYY. Ví dụ ngày 31 tháng 3 năm 2024 thì sẽ điền là: 31/03/2024 | EG4: Số năm sử dụng các tài sản cố định được quy định trong thông tư 23/2023/TT-BTC theo từng loại tài sản | EH4: Là phần trăm mức độ giảm giá trị theo năm do điều kiện tự nhiên, hoạt động vận hành,... | EI4: Ngày kết thúc tính hao mòn đối với tài sản người dùng sẽ nhập theo định dạng DD/MM/YYYY. Ví dụ ngày 31 tháng 3 năm 2024 thì sẽ điền là: 31/03/2024 | EJ4: Ngày bắt đầu trích khấu hao đối với tài sản người dùng sẽ nhập theo định dạng DD/MM/YYYY. Ví dụ ngày 31 tháng 3 năm 2024 thì sẽ điền là: 31/03/2024 | EK4: Loại kỳ trích khấu hao, Người dùng sẽ chọn: Tháng hoặc Năm | EL4: Số tháng được dùng để trích khấu hao | EM4: Số năm mà tài sản được trích khấu hao tối thiểu | EN4: Số năm mà tài sản được trích khấu hao tối đa | EO4: Tổng hao mòn và khấu hao đã tính đến trước thời điểm khai báo | EP4: Giá trị còn lại bằng nguyên giá trừ lũy kế
N5: Danh sách các nguồn hình thành:
N6: Nguồn NSNN cấp
N7: Ngân sách trung ương
N8: Ngân sách trung ương tự chủ
N9: Ngân sách trung ương không tự chủ
N10: Nguồn viện trợ, biếu tặng nhỏ lẻ, xã hội hóa
N11: Ngân sách Tỉnh
N12: Ngân sách Tỉnh tự chủ
N13: Ngân sách Tỉnh không tự chủ
N14: Ngân sách Huyện
N15: Ngân sách Huyện tự chủ
N16: Ngân sách Huyện không tự chủ
N17: Ngân sách Xã

Sheet AssetCategories
A1: 10_Quyền sử dụng đất | B1: 5 | C1: 10 | D1: 10 | E1: 10
A3: 9_Tài sản cố định hữu hình khác | B3: 5 | C3: 10 | D3: 10 | E3: 10
A5: 5_Xe ô tô | B5: 5 | C5: 10 | D5: 10 | E5: 10
A6: 42_Xe ô tô phục vụ công tác các chức danh | B6: 6 | C6: 10 | D6: 6.67 | E6: 15
A7: 45_Xe ô tô phục vụ công tác chung | B7: 6 | C7: 10 | D7: 6.67 | E7: 15
A8: 50_Xe ô tô chuyên dùng | B8: 6 | C8: 10 | D8: 6.67 | E8: 15
A9: 115_Xe ô tô phục vụ lễ tân nhà nước | B9: 6 | C9: 10 | D9: 6.67 | E9: 15
A10: 116_Xe ô tô khác | B10: 6 | C10: 10 | D10: 6.67 | E10: 15
A11: 43_Xe 4 đến 5 chỗ | B11: 6 | C11: 10 | D11: 6.67 | E11: 15
A12: 44_Xe 6 đến 8 chỗ | B12: 6 | C12: 10 | D12: 6.67 | E12: 15
A13: 46_Xe 4 đến 5 chỗ | B13: 6 | C13: 10 | D13: 6.67 | E13: 15
A14: 47_Xe 6 đến 8 chỗ | B14: 6 | C14: 10 | D14: 6.67 | E14: 15
... A80: 114_Xe khác phục vụ nhiệm vụ đặc thù | B80: 6 | C80: 10 | D80: 6.67 | E80: 15
A81: 217_Xe chở phạm nhân | D81: 6.67 | E81: 15
A83: 6_Phương tiện vận tải khác | B83: 5 | C83: 10 | D83: 10 | E83: 10
A84: 117_Phương tiện vận tải đường bộ | B84: 6 | C84: 10 | D84: 10 | E84: 10
A85: 118_Phương tiện vận tải đường sắt | B85: 7 | C85: 15 | D85: 10 | E85: 10
A86: 119_Phương tiện vận tải đường thủy | B86: 7 | C86: 15 | D86: 10 | E86: 10
A87: 129_Phương tiện vận tải hàng không | B87: 8 | C87: 20 | D87: 10 | E87: 10
A88: 130_Phương tiện vận tải khác | D88: 10 | E88: 10
A89: 120_Tàu biển chở hàng hóa | B89: 7 | C89: 15 | D89: 10 | E89: 10
A90: 121_Tàu biển chở khách | B90: 7 | C90: 15 | D90: 10 | E90: 10
A91: 122_Tàu tuần tra, cứu hộ, cứu nạn đường thủy | B91: 7 | C91: 15 | D91: 10 | E91: 10
A92: 123_Tàu chở hàng đường thủy nội địa | B92: 7 | C92: 15 | D92: 10 | E92: 10
A93: 124_Tàu chở khách đường thủy nội địa | B93: 7 | C93: 15 | D93: 10 | E93: 10
A94: 125_Phà đường thủy các loại | B94: 7 | C94: 15 | D94: 10 | E94: 10
A95: 126_Ca nô, xuồng máy các loại | B95: 7 | C95: 15 | D95: 10 | E95: 10
A96: 127_Ghe, thuyền các loại | B96: 7 | C96: 15 | D96: 10 | E96: 10
A97: 128_Phương tiện vận tải đường thủy khác | B97: 7 | C97: 15 | D97: 10 | E97: 10
A99: 8_Cây lâu năm, súc vật làm việc | B99: 5 | C99: 10 | D99: 10 | E99: 10
A100: 207_Các loại súc vật | B100: 4 | C100: 15 | D100: 12.5 | E100: 8
A101: 208_Cây lâu năm, vườn cây lâu năm (bao gồm cả vườn cây công nghiệp, vườn cây ăn quả, vườn cây cảnh) | B101: 6 | C101: 40 | D101: 4 | E101: 25
... A109: 38_Cấp IV | B109: 25 | C109: 50 | D109: 6.67 | E109: 15
A110: 233_Tài sản giả
A111: 220_Penhouse | B111: 15 | C111: 30 | D111: 10 | E111: 20
A113: 4_Vật kiến trúc | B113: 5 | C113: 10 | D113: 10 | E113: 10
A114: 39_Kho chứa, bể chứa, bãi đỗ, sân phơi, sân chơi, sân thể thao, bể bơi | B114: 5 | C114: 20 | D114: 5 | E114: 20
A115: 40_Giếng khoan, giếng đào, tường rào | B115: 6 | C115: 25 | D115: 10 | E115: 10
A116: 41_Các vật kiến trúc khác | B116: 6 | C116: 25 | D116: 10 | E116: 10
A118: 7_Máy móc, thiết bị | B118: 5 | C118: 10 | D118: 10 | E118: 10
...

Sheet Location
A2: 34_phòng ban 102 - viện quốc tế | B2: 31_phòng 411 | C2: 33_phòng ban 101 - viện quốc tế
A3: 37_phòng 202B- vđt QTế | B3: 32_phòng ban quốc tế 1 | C3: 36_phòng 201A- vđt quốc tế
B4: 35_phòng 201 - viện đào tạo quốc tế

Sheet Department
A1: STT_12_Phongbanso2Viendaotaoquocte1
A2: STT_8_VienDaotaoQuocteveKhoahocVatlieuITIMS
A3: STT_11_Phongbanso1Viendaotaoquocte

Sheet Units
A2: 48_bộ | B2: 43_bộ | C2: 23_bộ | D2: 28_bộ | E2: 38_bộ | F2: 10_chiếc | G2: 6_chiếc | H2: 33_bộ
A3: 49_căn | B3: 44_căn | C3: 24_căn | D3: 29_căn | E3: 39_căn | F3: 11_bộ | G3: 19_bộ | H3: 34_căn
A4: 50_mảnh | B4: 45_mảnh | C4: 25_mảnh | D4: 30_mảnh | E4: 40_mảnh | F4: 12_cái | G4: 20_căn | H4: 35_mảnh
A5: 51_cái | B5: 46_cái | C5: 26_cái | D5: 31_cái | E5: 41_cái | G5: 21_mảnh | H5: 36_cái

Sheet DocumentAttacks
A2: 11_Tài liệu số 06 | B2: 11_Tài liệu số 06 | C2: 11_Tài liệu số 06
A3: 12_Tài liệu số 07 | B3: 12_Tài liệu số 07 | C3: 12_Tài liệu số 07
A4: 16_QD121212 | B4: 16_QD121212 | C4: 16_QD121212

Sheet Projects
A1: 1_DA01
A2: 2_DA02
A3: 17_Dự án số 100
A4: 4_DA011
A5: 6_DA021
A6: 7_DA022
A7: 8_DA0111
A8: 9_DA0112
A9: 10_DA0211
A10: 11_DA0221
A11: 12_DA0121
A12: 14_DA0221
A13: 16_Dự án ABC

Sheet Provinces
A1: STT_01_HaNoi
A2: STT_02_HaGiang
A3: STT_04_CaoBang
A4: STT_06_BacKan
A5: STT_08_TuyenQuang
A6: STT_10_LaoCai
A7: STT_11_DienBien
A8: STT_12_LaiChau
A9: STT_14_SonLa
A10: STT_15_YenBai
A11: STT_17_HoaBinh
A12: STT_19_ThaiNguyen
... A63: STT_96_CaMau

Sheet Districts
A2: STT_338_QuynhPhu | B2: STT_584_BacAi | C2: STT_748_BaRia | D2: STT_705_TanBien | E2: STT_071_LamBinh | F2: STT_150_DaBac | G2: STT_689_DongXoai | H2: STT_761_12 | I2: STT_844_CangLong | J2: STT_476_PhongDien | K2: STT_359_VuBan | L2: STT_462_QuangTri | M2: STT_569_CamRanh | N2: STT_623_AnKhe | O2: STT_325_VanLam | P2: STT_095_MuongLay | Q2: STT_180_TrangDinh | R2: STT_106_TamDuong | S2: STT_026_DongVan | T2: STT_370_TamDiep | U2: STT_503_HoiAn | V2: STT_042_BaoLam | W2: STT_349_DuyTien | X2: STT_857_LongHo | Y2: STT_542_AnLao | Z2: STT_966_UMinh | AA2: STT_900_HaTien | AB2: STT_215_YenThe | AC2: STT_942_ChauThanh | AD2: STT_867_SaDec | AE2: STT_719_BauBang | AF2: STT_413_CuaLo | AG2: STT_258_YenPhong | AH2: STT_610_DakGlei | AI2: STT_795_KienTuong | AJ2: STT_304_NgoQuyen | AK2: STT_290_ChiLinh | AL2: STT_228_PhuTho | AM2: STT_673_BaoLoc | AN2: STT_437_HongLinh | AO2: STT_452_MinhHoa | AP2: STT_831_ChauThanh | AQ2: STT_557_SongCau | AR2: STT_956_HongDan | AS2: STT_082_BatXat | AT2: STT_244_PhucYen | AU2: STT_381_BimSon | AV2: STT_884_ChauDoc | AW2: STT_816_GoCong | AX2: STT_133_NghiaLo | AY2: STT_931_NgaBay | AZ2: STT_524_BinhSon | BA2: STT_661_DakGlong | BB2: STT_165_SongCong | BC2: STT_917_OMon | BD2: STT_594_LaGi | BE2: STT_002_HoanKiem | BF2: STT_118_QuynhNhai | BG2: STT_491_ThanhKhe | BH2: STT_194_MongCai | BI2: STT_644_BuonHo | BJ2: STT_060_PacNam | BK2: STT_732_LongKhanh
A3: STT_339_HungHa | B3: STT_585_NinhSon | C3: STT_750_ChauDuc | D3: STT_706_TanChau | E3: STT_072_NaHang | F3: STT_152_LuongSon | G3: STT_690_BinhLong | H3: STT_764_GoVap | I3: STT_845_CauKe | J3: STT_477_QuangDien | K3: STT_360_YYen | L3: STT_464_VinhLinh | M3: STT_570_CamLam | N3: STT_624_AyunPa | O3: STT_326_VanGiang | P3: STT_096_MuongNhe | Q3: STT_181_BinhGia | R3: STT_107_MuongTe | S3: STT_027_MeoVac | T3: STT_372_NhoQuan | U3: STT_504_TayGiang | V3: STT_043_BaoLac | W3: STT_350_KimBang | X3: STT_858_MangThit | Y3: STT_543_HoaiNhon | Z3: STT_967_ThoiBinh | AA3: STT_902_KienLuong | AB3: STT_216_TanYen | AC3: STT_943_KeSach | AD3: STT_868_HongNgu | AE3: STT_720_DauTieng | AF3: STT_414_ThaiHoa | AG3: STT_259_QueVo | AH3: STT_611_NgocHoi | AI3: STT_796_TanHung | AJ3: STT_305_LeChan | AK3: STT_291_NamSach | AL3: STT_230_DoanHung | AM3: STT_674_DamRong | AN3: STT_439_HuongSon | AO3: STT_453_TuyenHoa | AP3: STT_832_ChoLach | AQ3: STT_558_DongXuan | AR3: STT_957_PhuocLong | AS3: STT_083_MuongKhuong | AT3: STT_246_LapThach | AU3: STT_382_SamSon | AV3: STT_886_AnPhu | AW3: STT_817_CaiLay | AX3: STT_135_LucYen | AY3: STT_932_ChauThanhA | AZ3: STT_525_TraBong | BA3: STT_662_CuJut | BB3: STT_167_DinhHoa | BC3: STT_918_BinhThuy | BD3: STT_595_TuyPhong | BE3: STT_003_TayHo | BF3: STT_119_ThuanChau | BG3: STT_492_HaiChau | BH3: STT_195_CamPha | BI3: STT_645_EaHleo | BJ3: STT_061_BaBe | BK3: STT_734_TanPhu
A4: STT_340_DongHung | B4: STT_586_NinhHai | C4: STT_751_XuyenMoc | D4: STT_707_DuongMinhChau | E4: STT_073_ChiemHoa | F4: STT_153_KimBoi | G4: STT_691_BuGiaMap | H4: STT_765_BinhThanh | I4: STT_846_TieuCan | J4: STT_478_PhuVang | K4: STT_361_NghiaHung | L4: STT_465_HuongHoa | M4: STT_571_VanNinh | N4: STT_625_KBang | O4: STT_327_YenMy | P4: STT_097_MuongCha | Q4: STT_182_VanLang | R4: STT_108_SinHo | S4: STT_028_YenMinh | T4: STT_373_GiaVien | U4: STT_505_DongGiang | V4: STT_045_HaQuang | W4: STT_351_ThanhLiem | X4: STT_859_VungLiem | Y4: STT_544_HoaiAn | Z4: STT_968_TranVanThoi | AA4: STT_903_HonDat | AB4: STT_217_LangGiang | AC4: STT_944_MyTu | AD4: STT_869_TanHong | AE4: STT_721_BenCat | AF4: STT_415_QuePhong | AG4: STT_260_TienDu | AH4: STT_612_DakTo | AI4: STT_797_VinhHung | AJ4: STT_306_HaiAn | AK4: STT_292_KinhMon | AL4: STT_231_HaHoa | AM4: STT_675_LacDuong | AN4: STT_440_DucTho | AO4: STT_454_QuangTrach | AP4: STT_833_MoCayNam | AQ4: STT_559_TuyAn | AR4: STT_958_VinhLoi | AS4: STT_084_SiMaCai | AT4: STT_247_TamDuong | AU4: STT_384_MuongLat | AV4: STT_887_TanChau | AW4: STT_818_TanPhuoc | AX4: STT_136_VanYen | AY4: STT_933_ChauThanh | AZ4: STT_527_SonTinh | BA4: STT_663_DakMil | BB4: STT_168_PhuLuong | BC4: STT_919_CaiRang | BD4: STT_596_BacBinh | BE4: STT_004_LongBien | BF4: STT_120_MuongLa | BG4: STT_493_SonTra | BH4: STT_196_UongBi | BI4: STT_646_EaSup | BJ4: STT_062_NganSon | BK4: STT_735_VinhCuu
A5: STT_341_ThaiThuy | B5: STT_587_NinhPhuoc | C5: STT_752_LongDien | D5: STT_708_ChauThanh | E5: STT_074_HamYen | F5: STT_154_CaoPhong | G5: STT_692_LocNinh | H5: STT_766_TanBinh | I5: STT_847_ChauThanh | J5: STT_479_HuongThuy | K5: STT_362_NamTruc | L5: STT_466_GioLinh | M5: STT_572_NinhHoa | N5: STT_626_DakDoa | O5: STT_328_MyHao | P5: STT_098_TuaChua | Q5: STT_183_CaoLoc | R5: STT_109_PhongTho | S5: STT_029_QuanBa | T5: STT_374_HoaLu | U5: STT_506_DaiLoc | V5: STT_047_TrungKhanh | W5: STT_352_BinhLuc | X5: STT_860_TamBinh | Y5: STT_545_PhuMy | Z5: STT_969_CaiNuoc | AA5: STT_904_TanHiep | AB5: STT_218_LucNam | AC5: STT_945_CuLaoDung | AD5: STT_870_HongNgu | AE5: STT_722_PhuGiao | AF5: STT_416_QuyChau | AG5: STT_261_TuSon | AH5: STT_613_KonPlong | AI5: STT_798_MocHoa | AJ5: STT_307_KienAn | AK5: STT_293_KimThanh | AL5: STT_232_ThanhBa | AM5: STT_676_LamHa | AN5: STT_441_VuQuang | AO5: STT_455_BoTrach | AP5: STT_834_GiongTrom | AQ5: STT_560_SonHoa | AR5: STT_959_GiaRai | AS5: STT_085_BacHa | AT5: STT_248_TamDao | AU5: STT_385_QuanHoa | AV5: STT_888_PhuTan | AW5: STT_819_CaiBe | AX5: STT_137_MuCangChai | AY5: STT_934_PhungHiep | AZ5: STT_528_TuNghia | BA5: STT_664_KrongNo | BB5: STT_169_DongHy | BC5: STT_923_ThotNot | BD5: STT_597_HamThuanBac | BE5: STT_005_CauGiay | BF5: STT_121_BacYen | BG5: STT_494_NguHanhSon | BH5: STT_198_BinhLieu | BI5: STT_647_BuonDon | BJ5: STT_063_BachThong | BK5: STT_736_DinhQuan
A6: STT_342_TienHai | B6: STT_588_ThuanBac | C6: STT_753_DatDo | D6: STT_709_HoaThanh | E6: STT_075_YenSon | F6: STT_155_TanLac | G6: STT_693_BuDop | H6: STT_767_TanPhu | I6: STT_848_CauNgang | J6: STT_480_HuongTra | K6: STT_363_TrucNinh | L6: STT_467_DaKrong | M6: STT_573_KhanhVinh | N6: STT_627_ChuPah | O6: STT_329_AnThi | P6: STT_099_TuanGiao | Q6: STT_184_VanQuan | R6: STT_110_ThanUyen | S6: STT_030_ViXuyen | T6: STT_375_YenKhanh | U6: STT_507_DienBan | V6: STT_048_HaLang | W6: STT_353_LyNhan | X6: STT_861_BinhMinh | Y6: STT_546_VinhThanh | Z6: STT_970_DamDoi | AA6: STT_905_ChauThanh | AB6: STT_219_LucNgan | AC6: STT_946_LongPhu | AD6: STT_871_TamNong | AE6: STT_723_TanUyen | AF6: STT_417_KySon | AG6: STT_262_ThuanThanh | AH6: STT_614_KonRay | AI6: STT_799_TanThanh | AJ6: STT_308_DoSon | AK6: STT_294_ThanhHa | AL6: STT_233_PhuNinh | AM6: STT_677_DonDuong | AN6: STT_442_NghiXuan | AO6: STT_456_QuangNinh | AP6: STT_835_BinhDai | AQ6: STT_561_SongHinh | AR6: STT_960_DongHai | AS6: STT_086_BaoThang | AT6: STT_249_BinhXuyen | AU6: STT_386_BaThuoc | AV6: STT_889_ChauPhu | AW6: STT_820_CaiLay | AX6: STT_138_TranYen | AY6: STT_935_ViThuy | AZ6: STT_529_SonHa | BA6: STT_665_DakSong | BB6: STT_170_VoNhai | BC6: STT_924_VinhThanh | BD6: STT_598_HamThuanNam | BE6: STT_006_DongDa | BF6: STT_122_PhuYen | BG6: STT_495_CamLe | BH6: STT_199_TienYen | BI6: STT_648_CuMgar | BJ6: STT_064_ChoDon | BK6: STT_737_TrangBom
A7: STT_343_KienXuong | B7: STT_589_ThuanNam | C7: STT_754_PhuMy | D7: STT_710_GoDau | E7: STT_076_SonDuong | F7: STT_156_MaiChau | G7: STT_694_HonQuan | H7: STT_768_PhuNhuan | I7: STT_849_TraCu | J7: STT_481_ALuoi | K7: STT_364_XuanTruong | L7: STT_468_CamLo | M7: STT_574_DienKhanh | N7: STT_628_IaGrai | O7: STT_330_KhoaiChau | P7: STT_100_DienBien | Q7: STT_185_BacSon | R7: STT_111_TanUyen | S7: STT_031_BacMe | T7: STT_376_KimSon | U7: STT_508_DuyXuyen | V7: STT_049_QuangHoa | X7: STT_862_TraOn | Y7: STT_547_TaySon | Z7: STT_971_NamCan | AA7: STT_906_GiongRieng | AB7: STT_220_SonDong | AC7: STT_947_MyXuyen | AD7: STT_872_ThapMuoi | AE7: STT_724_DiAn | AF7: STT_418_TuongDuong | AG7: STT_263_GiaBinh | AH7: STT_615_DakHa | AI7: STT_800_ThanhHoa | AJ7: STT_309_DuongKinh | AK7: STT_295_CamGiang | AL7: STT_234_YenLap | AM7: STT_678_DucTrong | AN7: STT_443_CanLoc | AO7: STT_457_LeThuy | AP7: STT_836_BaTri | AQ7: STT_562_TayHoa | AR7: STT_961_HoaBinh | AS7: STT_087_BaoYen | AT7: STT_251_YenLac | AU7: STT_387_QuanSon | AV7: STT_890_TinhBien | AW7: STT_821_ChauThanh | AX7: STT_139_TramTau | AY7: STT_936_LongMy | AZ7: STT_530_SonTay | BA7: STT_666_DakRLap | BB7: STT_171_DaiTu | BC7: STT_925_CoDo | BD7: STT_599_TanhLinh | BE7: STT_007_HaiBaTrung | BF7: STT_123_MocChau | BG7: STT_497_HoaVang | BH7: STT_200_DamHa | BI7: STT_649_KrongBuk | BJ7: STT_065_ChoMoi | BK7: STT_738_ThongNhat
A8: STT_344_VuThu | D8: STT_711_BenCau | F8: STT_157_LacSon | G8: STT_695_DongPhu | H8: STT_769_ThuDuc | I8: STT_850_DuyenHai | J8: STT_482_PhuLoc | K8: STT_365_GiaoThuy | L8: STT_469_TrieuPhong | M8: STT_575_KhanhSon | N8: STT_629_MangYang | O8: STT_331_KimDong | P8: STT_101_DienBienDong | Q8: STT_186_HuuLung | R8: STT_112_NamNhun | S8: STT_032_HoangSuPhi | T8: STT_377_YenMo | U8: STT_509_QueSon | V8: STT_051_HoaAn | X8: STT_863_BinhTan | Y8: STT_548_PhuCat | Z8: STT_972_PhuTan | AA8: STT_907_GoQuao | AB8: STT_221_YenDung | AC8: STT_948_NgaNam | AD8: STT_873_CaoLanh | AE8: STT_725_ThuanAn | AF8: STT_419_NghiaDan | AG8: STT_264_LuongTai | AH8: STT_616_SaThay | AI8: STT_801_DucHue | AJ8: STT_311_ThuyNguyen | AK8: STT_296_BinhGiang | AL8: STT_235_CamKhe | AM8: STT_679_DiLinh | AN8: STT_444_HuongKhe | AO8: STT_458_BaDon | AP8: STT_837_ThanhPhu | AQ8: STT_563_PhuHoa | AS8: STT_088_SaPa | AT8: STT_252_VinhTuong | AU8: STT_388_LangChanh | AV8: STT_891_TriTon | AW8: STT_822_ChoGao | AX8: STT_140_VanChan | AY8: STT_937_LongMy | AZ8: STT_531_MinhLong | BA8: STT_667_TuyDuc | BB8: STT_172_PhoYen | BC8: STT_926_PhongDien | BD8: STT_600_DucLinh | BE8: STT_008_HoangMai | BF8: STT_124_YenChau | BH8: STT_201_HaiHa | BI8: STT_650_KrongNang | BJ8: STT_066_NaRi | BK8: STT_739_CamMy
D9: STT_712_TrangBang | F9: STT_158_YenThuy | G9: STT_696_BuDang | H9: STT_770_3 | I9: STT_851_DuyenHai | J9: STT_483_NamDong | K9: STT_366_HaiHau | L9: STT_470_HaiLang | M9: STT_576_TruongSa | N9: STT_630_KongChro | O9: STT_332_TienLu | P9: STT_102_Muongng | Q9: STT_187_ChiLang | S9: STT_033_XinMan | U9: STT_510_NamGiang | V9: STT_052_NguyenBinh | Y9: STT_549_AnNhon | Z9: STT_973_NgocHien | AA9: STT_908_AnBien | AB9: STT_222_VietYen | AC9: STT_949_ThanhTri | AD9: STT_874_ThanhBinh | AE9: STT_726_BacTanUyen | AF9: STT_420_QuyHop | AH9: STT_617_TuMoRong | AI9: STT_802_DucHoa | AJ9: STT_312_AnDuong | AK9: STT_297_GiaLoc | AL9: STT_236_TamNong | AM9: STT_680_BaoLam | AN9: STT_445_ThachHa | AP9: STT_838_MoCayBac | AQ9: STT_564_DongHoa | AS9: STT_089_VanBan | AT9: STT_253_SongLo | AU9: STT_389_NgocLac | AV9: STT_892_ChauThanh | AW9: STT_823_GoCongTay | AX9: STT_141_YenBinh | AZ9: STT_532_NghiaHanh | BB9: STT_173_PhuBinh | BC9: STT_927_ThoiLai | BD9: STT_601_HamTan | BE9: STT_009_ThanhXuan | BF9: STT_125_MaiSon | BH9: STT_202_BaChe | BI9: STT_651_EaKar | BK9: STT_740_LongThanh
F10: STT_159_LacThuy | G10: STT_697_ChonThanh | H10: STT_771_10 | N10: STT_631_DucCo | O10: STT_333_PhuCu | P10: STT_103_NamPo | Q10: STT_188_LocBinh | S10: STT_034_BacQuang | U10: STT_511_PhuocSon | V10: STT_053_ThachAn | Y10: STT_550_TuyPhuoc | AA10: STT_909_AnMinh | AB10: STT_223_HiepHoa | AC10: STT_950_VinhChau | AD10: STT_875_LapVo | AF10: STT_421_QuynhLuu | AH10: STT_618_IaHDrai | AI10: STT_803_BenLuc | AJ10: STT_313_AnLao | AK10: STT_298_TuKy | AL10: STT_237_LamThao | AM10: STT_681_DaHuoai | AN10: STT_446_CamXuyen | AU10: STT_390_CamThuy | AV10: STT_893_ChoMoi | AW10: STT_824_GoCongDong | AZ10: STT_533_MoDuc | BD10: STT_602_PhuQui | BE10: STT_016_SocSon | BF10: STT_126_SongMa | BH10: STT_203_VanDon | BI10: STT_652_MDrak | BK10: STT_741_XuanLoc
G11: STT_698_PhuRieng | H11: STT_772_11 | N11: STT_632_ChuProng | Q11: STT_189_DinhLap | S11: STT_035_QuangBinh | U11: STT_512_HiepDuc | Y11: STT_551_VanCanh | AA11: STT_910_VinhThuan | AC11: STT_951_TranDe | AD11: STT_876_LaiVung | AF11: STT_422_ConCuong | AI11: STT_804_ThuThua | AJ11: STT_314_KienThuy | AK11: STT_299_NinhGiang | AL11: STT_238_ThanhSon | AM11: STT_682_DaTeh | AN11: STT_447_KyAnh | AU11: STT_391_ThachThanh | AV11: STT_894_ThoaiSon | AW11: STT_825_TanPhuDong | AZ11: STT_534_DucPho | BE11: STT_017_DongAnh | BF11: STT_127_SopCop | BH11: STT_205_DongTrieu | BI11: STT_653_KrongBong | BK11: STT_742_NhonTrach
H12: STT_773_4 | N12: STT_633_ChuSe | U12: STT_513_ThangBinh | AA12: STT_911_PhuQuoc | AD12: STT_877_ChauThanh | AF12: STT_423_TanKy | AI12: STT_805_TanTru | AJ12: STT_315_TienLang | AK12: STT_300_ThanhMien | AL12: STT_239_ThanhThuy | AM12: STT_683_CatTien | AN12: STT_448_LocHa | AU12: STT_392_HaTrung | AZ12: STT_535_BaTo | BE12: STT_018_GiaLam | BF12: STT_128_VanHo | BH12: STT_206_QuangYen | BI12: STT_654_KrongPac
H13: STT_774_5 | N13: STT_634_DakPo | U13: STT_514_TienPhuoc | AA13: STT_912_KienHai | AF13: STT_424_AnhSon | AI13: STT_806_CanDuoc | AJ13: STT_316_VinhBao | AL13: STT_240_TanSon | AN13: STT_449_KyAnh | AU13: STT_393_VinhLoc | BE13: STT_019_NamTuLiem | BH13: STT_207_CoTo | BI13: STT_655_KrongANa
H14: STT_775_6 | N14: STT_635_IaPa | U14: STT_515_BacTraMy | AA14: STT_913_UMinhThuong | AF14: STT_425_DienChau | AI14: STT_807_CanGiuoc | AJ14: STT_317_CatHai | AU14: STT_394_YenDinh | BE14: STT_020_ThanhTri | BI14: STT_656_Lak
H15: STT_776_8 | N15: STT_637_KrongPa | U15: STT_516_NamTraMy | AA15: STT_914_GiangThanh | AF15: STT_426_YenThanh | AI15: STT_808_ChauThanh | AU15: STT_395_ThoXuan | BE15: STT_021_BacTuLiem | BI15: STT_657_CuKuin
H16: STT_777_BinhTan | N16: STT_638_PhuThien | U16: STT_517_NuiThanh | AF16: STT_427_DoLuong | AU16: STT_396_ThuongXuan | BE16: STT_250_MeLinh
H17: STT_778_7 | N17: STT_639_ChuPuh | U17: STT_518_PhuNinh | AF17: STT_428_ThanhChuong | AU17: STT_397_TrieuSon | BE17: STT_268_HaDong
H18: STT_783_CuChi | U18: STT_519_NongSon | AF18: STT_429_NghiLoc | AU18: STT_398_ThieuHoa | BE18: STT_269_SonTay
H19: STT_784_HocMon | AF19: STT_430_NamDan | AU19: STT_399_HoangHoa | BE19: STT_271_BaVi
H20: STT_785_BinhChanh | AF20: STT_431_HungNguyen | AU20: STT_400_HauLoc | BE20: STT_272_PhucTho
H21: STT_786_NhaBe | AF21: STT_432_HoangMai | AU21: STT_401_NgaSon | BE21: STT_273_DanPhuong
H22: STT_787_CanGio | AU22: STT_402_NhuXuan | BE22: STT_274_HoaiDuc
AU23: STT_403_NhuThanh | BE23: STT_275_QuocOai
AU24: STT_404_NongCong | BE24: STT_276_ThachThat
AU25: STT_405_DongSon | BE25: STT_277_ChuongMy
AU26: STT_406_QuangXuong | BE26: STT_278_ThanhOai
AU27: STT_407_NghiSon | BE27: STT_279_ThuongTin
BE28: STT_280_PhuXuyen
BE29: STT_281_UngHoa
BE30: STT_282_MyDuc

Sheet Wards
